Workbook

Sheet Portada
C10: La presente página permite al usuario consultar las tarifas históricas y vigentes, para ello escoja el año que desea consultar o bien la opción de tarifas vigentes para ver el pliego actual.
C21: 2013 | D21: 2014 | E21: 2015 | F21: 2016 | G21: 2017 | H21: 2018 | I21: 2019 | J21: 2020 | K21: 2021 | L21: 2022 | M21: 2023 | N21: 2024 | O21: 2025 | P21: Tarifas Vigentes
C23: Última actualización: | E23: 46010

Sheet 2013
B2: Seleccione la empresa que desea consultar:

Sheet ICE 2013
A5: Tabla 1
A6: Tarifas del servicio de generación eléctrica prestado por el ICE para el año 2013, según el mes y el tipo de tarifa respectivo.
A7: Tipo de tarifa y bloque | B7: Enero | C7: Febrero | D7: Marzo | E7: Abril | F7: Mayo | G7: Junio | H7: Julio | I7: Agosto | J7: Septiembre | K7: Octubre | L7: Noviembre | M7: Diciembre
A8: Ventas a ICE distribución y a la CNFL
A9: T-CB
A10: Energía_Punta | B10: 40.5 | C10: 40.5 | D10: 40.5 | E10: 62.993333 | F10: 64.6 | G10: 64.6 | H10: 62.8 | I10: 62.8 | J10: 62.8 | K10: 46.1 | L10: 46.1 | M10: 46.1
A11: Energía_Valle | B11: 47.6 | C11: 47.6 | D11: 43.625806 | E11: 52.846667 | F11: 53.1 | G11: 53.1 | H11: 51.5 | I11: 51.5 | J11: 51.5 | K11: 37.8 | L11: 37.8 | M11: 37.8
A12: Energía_Noche | B12: 40.5 | C12: 40.5 | D12: 37.158065 | E12: 44.986667 | F12: 45.2 | G12: 45.2 | H12: 43.7 | I12: 43.7 | J12: 43.7 | K12: 32.1 | L12: 32.1 | M12: 32.1
A13: Potencia_Punta | B13: 3082 | C13: 3082 | D13: 2825.4839 | E13: 3420.6 | F13: 3437 | G13: 3437 | H13: 3332 | I13: 3332 | J13: 3332 | K13: 2444 | L13: 2444 | M13: 2444
A14: Potencia_Valle | B14: 3082 | C14: 3082 | D14: 2825.4839 | E14: 3420.6 | F14: 3437 | G14: 3437 | H14: 3332 | I14: 3332 | J14: 3332 | K14: 2444 | L14: 2444 | M14: 2444
A15: VENTAS AL SERVICIO DE DISTRIBUCIÓN
A16: T-SD
A17: Energía_Punta | B17: 57.4 | C17: 57.4 | D17: 52.522581 | E17: 63.593333 | F17: 63.9 | G17: 63.9 | H17: 62 | I17: 62 | J17: 62 | K17: 45.5 | L17: 45.5 | M17: 45.5
A18: Energía_Valle | B18: 46.9 | C18: 46.9 | D18: 43.016129 | E18: 52.053333 | F18: 52.3 | G18: 52.3 | H18: 50.8 | I18: 50.8 | J18: 50.8 | K18: 37.3 | L18: 37.3 | M18: 37.3
A19: Energía_Noche | B19: 40.2 | C19: 40.2 | D19: 36.677419 | E19: 44.386667 | F19: 44.6 | G19: 44.6 | H19: 43.4 | I19: 43.4 | J19: 43.4 | K19: 31.8 | L19: 31.8 | M19: 31.8
A20: Potencia_Punta | B20: 3082 | C20: 3082 | D20: 2825.4839 | E20: 3420.6 | F20: 3437 | G20: 3437 | H20: 3332 | I20: 3332 | J20: 3332 | K20: 2444 | L20: 2444 | M20: 2444
A21: Potencia_Valle | B21: 3082 | C21: 3082 | D21: 2825.4839 | E21: 3420.6 | F21: 3437 | G21: 3437 | H21: 3332 | I21: 3332 | J21: 3332 | K21: 2444 | L21: 2444 | M21: 2444
A22: USUARIOS DIRECTOS
A23: T-UD
A24: Energía_Punta | B24: 0.078 | C24: 0.078 | D24: 0.078 | E24: 0.081533333 | F24: 0.081 | G24: 0.081 | H24: 0.063 | I24: 0.063 | J24: 0.063 | K24: 0.051 | L24: 0.051 | M24: 0.051
A25: Energía_Valle | B25: 0.064 | C25: 0.064 | D25: 0.064 | E25: 0.0674 | F25: 0.067 | G25: 0.067 | H25: 0.052 | I25: 0.052 | J25: 0.052 | K25: 0.042 | L25: 0.042 | M25: 0.042
A26: Energía_Noche | B26: 0.055 | C26: 0.055 | D26: 0.055 | E26: 0.057333333 | F26: 0.057 | G26: 0.057 | H26: 0.044 | I26: 0.044 | J26: 0.044 | K26: 0.036 | L26: 0.036 | M26: 0.036
A27: Potencia_Punta | B27: 4.15 | C27: 4.15 | D27: 4.15 | E27: 4.3566667 | F27: 4.33 | G27: 4.33 | H27: 3.39 | I27: 3.39 | J27: 3.39 | K27: 2.71 | L27: 2.71 | M27: 2.71
A28: Potencia_Valle | B28: 4.15 | C28: 4.15 | D28: 4.15 | E28: 4.3566667 | F28: 4.33 | G28: 4.33 | H28: 3.39 | I28: 3.39 | J28: 3.39 | K28: 2.71 | L28: 2.71 | M28: 2.71
A29: RESIDENCIAL
A30: T-RE
A31: Primeros 200 KWh | B31: 87 | C31: 87 | D31: 83.387097 | E31: 91.8 | F31: 92 | G31: 92 | H31: 88 | I31: 88 | J31: 88 | K31: 76 | L31: 76 | M31: 76
A32: De 201 a 300 KWh | B32: 159 | C32: 159 | D32: 149.96774 | E32: 164.66667 | F32: 165 | G32: 165 | H32: 159 | I32: 159 | J32: 159 | K32: 137 | L32: 137 | M32: 137
A33: kWh adicional | B33: 159 | C33: 159 | D33: 149.96774 | E33: 164.66667 | F33: 165 | G33: 165 | H33: 159 | I33: 159 | J33: 159 | K33: 137 | L33: 137 | M33: 137
A34: GENERAL
A35: T-GE
A36: Energía_Bloq. ≤3.000 KWh | B36: 130 | C36: 130 | D36: 125.48387 | E36: 137.73333 | F36: 138 | G36: 138 | H36: 133 | I36: 133 | J36: 133 | K36: 115 | L36: 115 | M36: 115
A37: Energía_Bloq. >3.000 KWh (KWh adicional) | B37: 78 | C37: 78 | D37: 75.290323 | E37: 82.866667 | F37: 83 | G37: 83 | H37: 80 | I37: 80 | J37: 80 | K37: 69 | L37: 69 | M37: 69
A38: Potencia_Mayor al diferencial (adicional) | B38: 12869 | C38: 12869 | D38: 12467.968 | E38: 13717.133 | F38: 13746 | G38: 13746 | H38: 13181 | I38: 13181 | J38: 13181 | K38: 11353 | L38: 11353 | M38: 11353
A39: PREFERENCIAL
A40: T-CS
A41: Energía_Bloq. ≤3.000 KWh | B41: 87 | C41: 87 | D41: 83.387097 | E41: 92.733333 | F41: 93 | G41: 93 | H41: 90 | I41: 90 | J41: 90 | K41: 77 | L41: 77 | M41: 77
A42: Energía_Bloq. >3.000 KWh (KWh adicional) | B42: 53 | C42: 53 | D42: 50.290323 | E42: 55.866667 | F42: 56 | G42: 56 | H42: 53 | I42: 53 | J42: 53 | K42: 46 | L42: 46 | M42: 46
A43: Potencia_Mayor al diferencial (adicional) | B43: 8530 | C43: 8530 | D43: 8139.8065 | E43: 8939.2 | F43: 8958 | G43: 8958 | H43: 8633 | I43: 8633 | J43: 8633 | K43: 7435 | L43: 7435 | M43: 7435
A44: MEDIA TENSIÓN (T-MT)
...

Sheet CNFL 2013
A4: Tabla 3
A5: Tarifas del servicio de distribución eléctrica y alumbrado público prestado por la CNFL para el año 2013, según el mes y el tipo de tarifa respectivo.
A6: Tipo de tarifa y bloque | B6: Enero | C6: Febrero | D6: Marzo | E6: Abril | F6: Mayo | G6: Junio | H6: Julio | I6: Agosto | J6: Septiembre | K6: Octubre | L6: Noviembre | M6: Diciembre
A7: RESIDENCIAL
A8: T-RE
A9: Primeros 200 KWh | B9: 69 | C9: 69 | D9: 69 | E9: 78.733333 | F9: 79 | G9: 79 | H9: 77 | I9: 77 | J9: 77 | K9: 64 | L9: 62 | M9: 62
A10: De 201 a 300 KWh | B10: 103 | C10: 103 | D10: 103 | E10: 115.66667 | F10: 116 | G10: 116 | H10: 118 | I10: 118 | J10: 118 | K10: 98 | L10: 95 | M10: 95
A11: kWh adicional | B11: 110 | C11: 110 | D11: 110 | E11: 124.6 | F11: 125 | G11: 125 | H11: 122 | I11: 122 | J11: 122 | K11: 101 | L11: 98 | M11: 98
A12: GENERAL
A13: T-GE
A14: Energía_Bloq. ≤3.000 KWh | B14: 115 | C14: 115 | D14: 115 | E14: 130.6 | F14: 131 | G14: 131 | H14: 129 | I14: 129 | J14: 129 | K14: 108 | L14: 105 | M14: 105
A15: Energía_Bloq. >3.000 KWh (primeros 3000 KWh) | B15: 213000 | C15: 213000 | D15: 213000 | E15: 239200 | F15: 240000 | G15: 240000 | H15: 234000 | I15: 234000 | J15: 234000 | K15: 195000 | L15: 189000 | M15: 189000
A16: Energía_Bloq. >3.000 KWh (KWh adicional) | B16: 71 | C16: 71 | D16: 71 | E16: 79.733333 | F16: 80 | G16: 80 | H16: 78 | I16: 78 | J16: 78 | K16: 65 | L16: 63 | M16: 63
A17: Potencia_Menor igual al diferencial (mínimo) | B17: 87440 | C17: 87440 | D17: 87440 | E17: 98772.267 | F17: 99080 | G17: 99080 | H17: 97584 | I17: 97584 | J17: 97584 | K17: 81248 | L17: 78824 | M17: 78824
A18: Potencia_Mayor al diferencial (adicional) | B18: 10930 | C18: 10930 | D18: 10930 | E18: 12346.533 | F18: 12385 | G18: 12385 | H18: 12198 | I18: 12198 | J18: 12198 | K18: 10156 | L18: 9853 | M18: 9853
A19: PREFERENCIAL
A20: T-CS
A21: Energía_Bloq. ≤3.000 KWh | B21: 77 | C21: 77 | D21: 77 | E21: 86.733333 | F21: 87 | G21: 87 | H21: 87 | I21: 87 | J21: 87 | K21: 73 | L21: 70 | M21: 70
A22: Energía_Bloq. >3.000 KWh (primeros 3000 KWh) | B22: 135000 | C22: 135000 | D22: 135000 | E22: 149600 | F22: 150000 | G22: 150000 | H22: 150000 | I22: 150000 | J22: 150000 | K22: 126000 | L22: 123000 | M22: 123000
A23: Energía_Bloq. >3.000 KWh (KWh adicional) | B23: 45 | C23: 45 | D23: 45 | E23: 49.866667 | F23: 50 | G23: 50 | H23: 50 | I23: 50 | J23: 50 | K23: 42 | L23: 41 | M23: 41
A24: Potencia_Menor igual al diferencial (mínimo) | B24: 58256 | C24: 58256 | D24: 58256 | E24: 65810.667 | F24: 66016 | G24: 66016 | H24: 65000 | I24: 65000 | J24: 65000 | K24: 54120 | L24: 52512 | M24: 52512
A25: Potencia_Mayor al diferencial (adicional) | B25: 7282 | C25: 7282 | D25: 7282 | E25: 8226.3333 | F25: 8252 | G25: 8252 | H25: 8125 | I25: 8125 | J25: 8125 | K25: 6765 | L25: 6564 | M25: 6564
A26: MEDIA TENSIÓN (T-MT)
A27: T-MT
A28: Energía_Punta | B28: 60 | C28: 60 | D28: 60 | E28: 67.8 | F28: 68 | G28: 68 | H28: 67 | I28: 67 | J28: 67 | K28: 55 | L28: 53 | M28: 53
A29: Energía_Valle | B29: 29 | C29: 29 | D29: 29 | E29: 32.866667 | F29: 33 | G29: 33 | H29: 33 | I29: 33 | J29: 33 | K29: 28 | L29: 27 | M29: 27
A30: Energía_Noche | B30: 22 | C30: 22 | D30: 22 | E30: 24.933333 | F30: 25 | G30: 25 | H30: 24 | I30: 24 | J30: 24 | K30: 20 | L30: 19 | M30: 19
A31: Potencia_Punta | B31: 10376 | C31: 10376 | D31: 10376 | E31: 11720.467 | F31: 11757 | G31: 11757 | H31: 11578 | I31: 11578 | J31: 11578 | K31: 9640 | L31: 9353 | M31: 9353
A32: Potencia_Valle | B32: 7381 | C32: 7381 | D32: 7381 | E32: 8338 | F32: 8364 | G32: 8364 | H32: 8237 | I32: 8237 | J32: 8237 | K32: 6858 | L32: 6655 | M32: 6655
A33: Potencia_Noche | B33: 4686 | C33: 4686 | D33: 4686 | E33: 5294.4667 | F33: 5311 | G33: 5311 | H33: 5229 | I33: 5229 | J33: 5229 | K33: 4354 | L33: 4225 | M33: 4225
A34: Residencial horaria
A35: T-REH
A36: Bloque 0-300 KWh Punta | B36: 146 | C36: 146 | D36: 146 | E36: 164.46667 | F36: 165 | G36: 165 | H36: 163 | I36: 163 | J36: 163 | K36: 135 | L36: 131 | M36: 131
A37: Bloque 0-300 KWh Valle | B37: 60 | C37: 60 | D37: 60 | E37: 67.8 | F37: 68 | G37: 68 | H37: 68 | I37: 68 | J37: 68 | K37: 57 | L37: 54 | M37: 54
A38: Bloque 0-300 KWh Noche | B38: 25 | C38: 25 | D38: 25 | E38: 27.933333 | F38: 28 | G38: 28 | H38: 28 | I38: 28 | J38: 28 | K38: 23 | L38: 22 | M38: 22
A39: Bloque 301-500 KWh Punta | B39: 166 | C39: 166 | D39: 166 | E39: 187.4 | F39: 188 | G39: 188 | H39: 186 | I39: 186 | J39: 186 | K39: 155 | L39: 149 | M39: 149
A40: Bloque 301-500 KWh Valle | B40: 67 | C40: 67 | D40: 67 | E40: 76.733333 | F40: 77 | G40: 77 | H40: 74 | I40: 74 | J40: 74 | K40: 62 | L40: 61 | M40: 61
A41: Bloque 301-500 KWh Noche | B41: 29 | C41: 29 | D41: 29 | E41: 32.866667 | F41: 33 | G41: 33 | H41: 32 | I41: 32 | J41: 32 | K41: 27 | L41: 26 | M41: 26
A42: Bloque más de 500 KWh Punta | B42: 196 | C42: 196 | D42: 196 | E42: 221.33333 | F42: 222 | G42: 222 | H42: 219 | I42: 219 | J42: 219 | K42: 182 | L42: 177 | M42: 177
A43: Bloque más de 500 KWh Valle | B43: 78 | C43: 78 | D43: 78 | E43: 88.733333 | F43: 89 | G43: 89 | H43: 88 | I43: 88 | J43: 88 | K43: 74 | L43: 71 | M43: 71
...

Sheet JASEC 2013
A4: Tabla 4
A5: Tarifas del servicio de distribución eléctrica y alumbrado público prestado por JASEC para el año 2013, según el mes y el tipo de tarifa respectivo.
A6: Tipo de tarifa y bloque | B6: Enero | C6: Febrero | D6: Marzo | E6: Abril | F6: Mayo | G6: Junio | H6: Julio | I6: Agosto | J6: Septiembre | K6: Octubre | L6: Noviembre | M6: Diciembre
A7: RESIDENCIAL
A8: T-RE
A9: Primeros 200 KWh | B9: 63 | C9: 63 | D9: 63 | E9: 69.8 | F9: 70 | G9: 70 | H9: 71 | I9: 71 | J9: 71 | K9: 61 | L9: 61 | M9: 61
A10: kWh adicional | B10: 77 | C10: 77 | D10: 77 | E10: 86.733333 | F10: 87 | G10: 87 | H10: 87 | I10: 87 | J10: 87 | K10: 74 | L10: 74 | M10: 74
A11: GENERAL
A12: T-GE
A13: Energía_Bloq. ≤3.000 KWh | B13: 86 | C13: 86 | D13: 86 | E13: 96.666667 | F13: 97 | G13: 97 | H13: 100 | I13: 100 | J13: 100 | K13: 86 | L13: 86 | M13: 86
A14: Energía_Bloq. >3.000 KWh (primeros 3000 KWh) | B14: 156000 | C14: 156000 | D14: 156000 | E14: 173400 | F14: 174000 | G14: 174000 | H14: 180000 | I14: 180000 | J14: 180000 | K14: 153000 | L14: 153000 | M14: 153000
A15: Energía_Bloq. >3.000 KWh (KWh adicional) | B15: 52 | C15: 52 | D15: 52 | E15: 57.8 | F15: 58 | G15: 58 | H15: 60 | I15: 60 | J15: 60 | K15: 51 | L15: 51 | M15: 51
A16: Potencia_Menor igual al diferencial (mínimo) | B16: 64648 | C16: 64648 | D16: 64648 | E16: 72629.333 | F16: 72864 | G16: 72864 | H16: 75016 | I16: 75016 | J16: 75016 | K16: 64096 | L16: 64096 | M16: 64096
A17: Potencia_Mayor al diferencial (adicional) | B17: 8081 | C17: 8081 | D17: 8081 | E17: 9078.6667 | F17: 9108 | G17: 9108 | H17: 9377 | I17: 9377 | J17: 9377 | K17: 8012 | L17: 8012 | M17: 8012
A18: PREFERENCIAL
A19: T-CS
A20: Energía_Bloq. ≤3.000 KWh | B20: 63 | C20: 63 | D20: 63 | E20: 69.8 | F20: 70 | G20: 70 | H20: 72 | I20: 72 | J20: 72 | K20: 62 | L20: 62 | M20: 62
A21: Energía_Bloq. >3.000 KWh (primeros 3000 KWh) | B21: 108000 | C21: 108000 | D21: 108000 | E21: 122600 | F21: 123000 | G21: 123000 | H21: 126000 | I21: 126000 | J21: 126000 | K21: 108000 | L21: 108000 | M21: 108000
A22: Energía_Bloq. >3.000 KWh (KWh adicional) | B22: 36 | C22: 36 | D22: 36 | E22: 40.866667 | F22: 41 | G22: 41 | H22: 42 | I22: 42 | J22: 42 | K22: 36 | L22: 36 | M22: 36
A23: Potencia_Menor igual al diferencial (mínimo) | B23: 43832 | C23: 43832 | D23: 43832 | E23: 49256.533 | F23: 49416 | G23: 49416 | H23: 50416 | I23: 50416 | J23: 50416 | K23: 43072 | L23: 43072 | M23: 43072
A24: Potencia_Mayor al diferencial (adicional) | B24: 5479 | C24: 5479 | D24: 5479 | E24: 6157.0667 | F24: 6177 | G24: 6177 | H24: 6302 | I24: 6302 | J24: 6302 | K24: 5384 | L24: 5384 | M24: 5384
A25: MEDIA TENSIÓN (T-MT)
A26: T-MT
A27: Energía_Punta | B27: 50 | C27: 50 | D27: 50 | E27: 55.8 | F27: 56 | G27: 56 | H27: 55 | I27: 55 | J27: 55 | K27: 47 | L27: 47 | M27: 47
A28: Energía_Valle | B28: 24 | C28: 24 | D28: 24 | E28: 26.933333 | F28: 27 | G28: 27 | H28: 27 | I28: 27 | J28: 27 | K28: 23 | L28: 23 | M28: 23
A29: Energía_Noche | B29: 17 | C29: 17 | D29: 17 | E29: 18.933333 | F29: 19 | G29: 19 | H29: 18 | I29: 18 | J29: 18 | K29: 16 | L29: 16 | M29: 16
A30: Potencia_Punta | B30: 8560 | C30: 8560 | D30: 8560 | E30: 9617.9333 | F30: 9649 | G30: 9649 | H30: 9688 | I30: 9688 | J30: 9688 | K30: 8277 | L30: 8277 | M30: 8277
A31: Potencia_Valle | B31: 6138 | C31: 6138 | D31: 6138 | E31: 6895.7333 | F31: 6918 | G31: 6918 | H31: 6947 | I31: 6947 | J31: 6947 | K31: 5935 | L31: 5935 | M31: 5935
A32: Potencia_Noche | B32: 4198 | C32: 4198 | D32: 4198 | E32: 4716.7333 | F32: 4732 | G32: 4732 | H32: 4752 | I32: 4752 | J32: 4752 | K32: 4060 | L32: 4060 | M32: 4060
A33: ALUMBRADO PÚBLICO
A34: T-AP
A35: Cada KWh | B35: 3.06 | C35: 3.06 | D35: 3.06 | E35: 3.06 | F35: 3.06 | G35: 3.06 | H35: 3.06 | I35: 3.06 | J35: 3.06 | K35: 3.06 | L35: 3.06 | M35: 3.06

Sheet ESPH 2013
A5: Tabla 5
A6: Tarifas del servicio de distribución eléctrica y alumbrado público prestado por ESPH para el año 2013, según el mes y el tipo de tarifa respectivo.
A7: Tipo de tarifa y bloque | B7: Enero | C7: Febrero | D7: Marzo | E7: Abril | F7: Mayo | G7: Junio | H7: Julio | I7: Agosto | J7: Septiembre | K7: Octubre | L7: Noviembre | M7: Diciembre
A8: RESIDENCIAL
A9: T-RE
A10: Primeros 200 KWh | B10: 67 | C10: 67 | D10: 67 | E10: 76.733333 | F10: 77 | G10: 77 | H10: 76 | I10: 76 | J10: 76 | K10: 64 | L10: 62 | M10: 62
A11: kWh adicional | B11: 89 | C11: 89 | D11: 89 | E11: 102.2 | F11: 103 | G11: 103 | H11: 99 | I11: 99 | J11: 99 | K11: 84 | L11: 80 | M11: 80
A12: GENERAL
A13: T-GE
A14: Energía_Bloq. ≤3.000 KWh | B14: 99 | C14: 99 | D14: 99 | E14: 113.6 | F14: 114 | G14: 114 | H14: 105 | I14: 105 | J14: 105 | K14: 89 | L14: 86 | M14: 86
A15: Energía_Bloq. >3.000 KWh (primeros 3000 KWh) | B15: 165000 | C15: 165000 | D15: 165000 | E15: 191200 | F15: 192000 | G15: 192000 | H15: 180000 | I15: 180000 | J15: 180000 | K15: 150000 | L15: 144000 | M15: 144000
A16: Energía_Bloq. >3.000 KWh (KWh adicional) | B16: 55 | C16: 55 | D16: 55 | E16: 63.733333 | F16: 64 | G16: 64 | H16: 60 | I16: 60 | J16: 60 | K16: 50 | L16: 48 | M16: 48
A17: Potencia_Menor igual al diferencial (mínimo) | B17: 90800 | C17: 90800 | D17: 90800 | E17: 104290 | F17: 104680 | G17: 104680 | H17: 96130 | I17: 96130 | J17: 96130 | K17: 81180 | L17: 78340 | M17: 78340
A18: Potencia_Mayor al diferencial (adicional) | B18: 9080 | C18: 9080 | D18: 9080 | E18: 10429 | F18: 10468 | G18: 10468 | H18: 9613 | I18: 9613 | J18: 9613 | K18: 8118 | L18: 7834 | M18: 7834
A19: PREFERENCIAL
A20: T-CS
A21: Energía_Bloq. ≤3.000 KWh | B21: 67 | C21: 67 | D21: 67 | E21: 76.733333 | F21: 77 | G21: 77 | H21: 76 | I21: 76 | J21: 76 | K21: 64 | L21: 62 | M21: 62
A22: Energía_Bloq. >3.000 KWh (primeros 3000 KWh) | B22: 135000 | C22: 135000 | D22: 135000 | E22: 155400 | F22: 156000 | G22: 156000 | H22: 156000 | I22: 156000 | J22: 156000 | K22: 132000 | L22: 129000 | M22: 129000
A23: Energía_Bloq. >3.000 KWh (KWh adicional) | B23: 45 | C23: 45 | D23: 45 | E23: 51.8 | F23: 52 | G23: 52 | H23: 52 | I23: 52 | J23: 52 | K23: 44 | L23: 43 | M23: 43
A24: Potencia_Menor igual al diferencial (mínimo) | B24: 71070 | C24: 71070 | D24: 71070 | E24: 81624.667 | F24: 81930 | G24: 81930 | H24: 82130 | I24: 82130 | J24: 82130 | K24: 69350 | L24: 66930 | M24: 66930
A25: Potencia_Mayor al diferencial (adicional) | B25: 7107 | C25: 7107 | D25: 7107 | E25: 8162.4667 | F25: 8193 | G25: 8193 | H25: 8213 | I25: 8213 | J25: 8213 | K25: 6935 | L25: 6693 | M25: 6693
A26: MEDIA TENSIÓN (T-MT)
A27: T-MT
A28: Energía_Punta | B28: 63 | C28: 63 | D28: 63 | E28: 72.733333 | F28: 73 | G28: 73 | H28: 70 | I28: 70 | J28: 70 | K28: 59 | L28: 57 | M28: 57
A29: Energía_Valle | B29: 32 | C29: 32 | D29: 32 | E29: 35.866667 | F29: 36 | G29: 36 | H29: 36 | I29: 36 | J29: 36 | K29: 30 | L29: 29 | M29: 29
A30: Energía_Noche | B30: 26 | C30: 26 | D30: 26 | E30: 29.866667 | F30: 30 | G30: 30 | H30: 29 | I30: 29 | J30: 29 | K30: 25 | L30: 24 | M30: 24
A31: Potencia_Punta | B31: 10497 | C31: 10497 | D31: 10497 | E31: 12055.933 | F31: 12101 | G31: 12101 | H31: 11682 | I31: 11682 | J31: 11682 | K31: 9864 | L31: 9520 | M31: 9520
A32: Potencia_Valle | B32: 7293 | C32: 7293 | D32: 7293 | E32: 8376.6667 | F32: 8408 | G32: 8408 | H32: 8118 | I32: 8118 | J32: 8118 | K32: 6855 | L32: 6615 | M32: 6615
A33: Potencia_Noche | B33: 4860 | C33: 4860 | D33: 4860 | E33: 5582.1333 | F33: 5603 | G33: 5603 | H33: 5410 | I33: 5410 | J33: 5410 | K33: 4568 | L33: 4408 | M33: 4408
A34: ALUMBRADO PÚBLICO
A35: T-AP
A36: Cada KWh | B36: 3.05 | C36: 3.05 | D36: 3.05 | E36: 3.05 | F36: 3.05 | G36: 3.05 | H36: 3.05 | I36: 3.05 | J36: 3.05 | K36: 3.05 | L36: 3.05 | M36: 3.05

Sheet CL 2013
A5: Tabla 6
A6: Tarifas del servicio de distribución eléctrica y alumbrado público prestado por Coopelesca R.L para el año 2013, según el mes y el tipo de tarifa respectivo.
A7: Tipo de tarifa y bloque | B7: Enero | C7: Febrero | D7: Marzo | E7: Abril | F7: Mayo | G7: Junio | H7: Julio | I7: Agosto | J7: Septiembre | K7: Octubre | L7: Noviembre | M7: Diciembre
A8: RESIDENCIAL
A9: T-RE
A10: Primeros 200 KWh | B10: 78 | C10: 78 | D10: 82.064516 | E10: 91.933333 | F10: 92 | G10: 92 | H10: 83 | I10: 83 | J10: 83 | K10: 78 | L10: 77 | M10: 77
A11: kWh adicional | B11: 96 | C11: 96 | D11: 101.22581 | E11: 114.86667 | F11: 115 | G11: 115 | H11: 102 | I11: 102 | J11: 102 | K11: 96 | L11: 95 | M11: 95
A12: GENERAL
A13: T-GE
A14: Energía_Bloq. ≤3.000 KWh | B14: 104 | C14: 104 | D14: 106.90323 | E14: 118.86667 | F14: 119 | G14: 119 | H14: 108 | I14: 108 | J14: 108 | K14: 101 | L14: 100 | M14: 100
A15: Energía_Bloq. >3.000 KWh (primeros 3000 KWh) | B15: 255000 | C15: 255000 | D15: 261967.74 | E15: 293600 | F15: 294000 | G15: 294000 | H15: 261000 | I15: 261000 | J15: 261000 | K15: 246000 | L15: 243000 | M15: 243000
A16: Energía_Bloq. >3.000 KWh (KWh adicional) | B16: 85 | C16: 85 | D16: 87.322581 | E16: 97.866667 | F16: 98 | G16: 98 | H16: 87 | I16: 87 | J16: 87 | K16: 82 | L16: 81 | M16: 81
A17: Potencia_Menor igual al diferencial (mínimo) | B17: 76845 | C17: 76845 | D17: 63638.226 | E17: 59058 | F17: 59120 | G17: 59120 | H17: 52960 | I17: 52960 | J17: 52960 | K17: 49850 | L17: 49140 | M17: 49140
A18: Potencia_Mayor al diferencial (adicional) | B18: 5123 | C18: 5123 | D18: 5289.6452 | E18: 5905.8 | F18: 5912 | G18: 5912 | H18: 5296 | I18: 5296 | J18: 5296 | K18: 4985 | L18: 4914 | M18: 4914
A19: MEDIA TENSIÓN (T-MT)
A20: T-MT
A21: Energía_Punta | B21: 86 | C21: 86 | D21: 87.16129 | E21: 96.866667 | F21: 97 | G21: 97 | H21: 86 | I21: 86 | J21: 86 | K21: 81 | L21: 80 | M21: 80
A22: Energía_Valle | B22: 73 | C22: 73 | D22: 73.580645 | E22: 80.933333 | F22: 81 | G22: 81 | H22: 73 | I22: 73 | J22: 73 | K22: 69 | L22: 68 | M22: 68
A23: Energía_Noche | B23: 66 | C23: 66 | D23: 66.580645 | E23: 72.933333 | F23: 73 | G23: 73 | H23: 66 | I23: 66 | J23: 66 | K23: 62 | L23: 61 | M23: 61
A24: Potencia_Punta | B24: 4971 | C24: 4971 | D24: 5029.0645 | E24: 5535.2 | F24: 5541 | G24: 5541 | H24: 4963 | I24: 4963 | J24: 4963 | K24: 4671 | L24: 4605 | M24: 4605
A25: Potencia_Valle | B25: 4971 | C25: 4971 | D25: 5029.0645 | E25: 5535.2 | F25: 5541 | G25: 5541 | H25: 4963 | I25: 4963 | J25: 4963 | K25: 4671 | L25: 4605 | M25: 4605
A26: ALUMBRADO PÚBLICO
A27: T-AP
A28: Cada KWh | B28: 3.71 | C28: 3.71 | D28: 3.8841935 | E28: 4.01 | F28: 4.01 | G28: 4.01 | H28: 4.01 | I28: 4.01 | J28: 4.01 | K28: 4.01 | L28: 4.01 | M28: 4.01

Sheet CG 2013
A5: Tabla 7
A6: Tarifas del servicio de distribución eléctrica y alumbrado público prestado por CoopeGuanacaste R.L para el año 2013, según el mes y el tipo de tarifa respectivo.
A7: Tipo de tarifa y bloque | B7: Enero | C7: Febrero | D7: Marzo | E7: Abril | F7: Mayo | G7: Junio | H7: Julio | I7: Agosto | J7: Septiembre | K7: Octubre | L7: Noviembre | M7: Diciembre
A8: RESIDENCIAL
A9: T-RE
A10: Primeros 200 KWh | B10: 70 | C10: 70 | D10: 70 | E10: 78.8 | F10: 79 | G10: 79 | H10: 76 | I10: 76 | J10: 76 | K10: 66 | L10: 64 | M10: 64
A11: kWh adicional | B11: 99 | C11: 99 | D11: 99 | E11: 110.73333 | F11: 111 | G11: 111 | H11: 106 | I11: 106 | J11: 106 | K11: 92 | L11: 90 | M11: 90
A12: GENERAL
A13: T-GE
A14: Energía_Bloq. ≤3.000 KWh | B14: 103 | C14: 103 | D14: 103 | E14: 116.66667 | F14: 117 | G14: 117 | H14: 111 | I14: 111 | J14: 111 | K14: 96 | L14: 94 | M14: 94
A15: Energía_Bloq. >3.000 KWh (primeros 3000 KWh) | B15: 192000 | C15: 192000 | D15: 192000 | E15: 218400 | F15: 219000 | G15: 219000 | H15: 210000 | I15: 210000 | J15: 210000 | K15: 183000 | L15: 180000 | M15: 180000
A16: Energía_Bloq. >3.000 KWh (KWh adicional) | B16: 64 | C16: 64 | D16: 64 | E16: 72.8 | F16: 73 | G16: 73 | H16: 70 | I16: 70 | J16: 70 | K16: 61 | L16: 60 | M16: 60
A17: Potencia_Menor igual al diferencial (mínimo) | B17: 96410 | C17: 96410 | D17: 96410 | E17: 108308.67 | F17: 108600 | G17: 108600 | H17: 104140 | I17: 104140 | J17: 104140 | K17: 90180 | L17: 87980 | M17: 87980
A18: Potencia_Mayor al diferencial (adicional) | B18: 9641 | C18: 9641 | D18: 9641 | E18: 10830.867 | F18: 10860 | G18: 10860 | H18: 10414 | I18: 10414 | J18: 10414 | K18: 9018 | L18: 8798 | M18: 8798
A19: MEDIA TENSIÓN (T-MT)
A20: T-MT
A21: Energía_Punta | B21: 87 | C21: 87 | D21: 87 | E21: 97.733333 | F21: 98 | G21: 98 | H21: 93 | I21: 93 | J21: 93 | K21: 80 | L21: 78 | M21: 78
A22: Energía_Valle | B22: 74 | C22: 74 | D22: 74 | E22: 82.8 | F22: 83 | G22: 83 | H22: 81 | I22: 81 | J22: 81 | K22: 70 | L22: 68 | M22: 68
A23: Energía_Noche | B23: 65 | C23: 65 | D23: 65 | E23: 73.8 | F23: 74 | G23: 74 | H23: 71 | I23: 71 | J23: 71 | K23: 62 | L23: 61 | M23: 61
A24: Potencia_Punta | B24: 3892 | C24: 3892 | D24: 3892 | E24: 4371.2667 | F24: 4383 | G24: 4383 | H24: 4204 | I24: 4204 | J24: 4204 | K24: 3640 | L24: 3552 | M24: 3552
A25: Potencia_Valle | B25: 3892 | C25: 3892 | D25: 3892 | E25: 4371.2667 | F25: 4383 | G25: 4383 | H25: 4204 | I25: 4204 | J25: 4204 | K25: 3640 | L25: 3552 | M25: 3552
A26: ALUMBRADO PÚBLICO
A27: T-AP
A28: Cada KWh | B28: 2.19 | C28: 2.19 | D28: 2.19 | E28: 2.19 | F28: 2.19 | G28: 2.19 | H28: 2.19 | I28: 2.19 | J28: 2.19 | K28: 2.19 | L28: 2.19 | M28: 2.19

Sheet CS 2013
A5: Tabla 8
A6: Tarifas del servicio de distribución eléctrica y alumbrado público prestado por CoopeSantos R.L para el año 2013, según el mes y el tipo de tarifa respectivo.
A7: Tipo de tarifa y bloque | B7: Enero | C7: Febrero | D7: Marzo | E7: Abril | F7: Mayo | G7: Junio | H7: Julio | I7: Agosto | J7: Septiembre | K7: Octubre | L7: Noviembre | M7: Diciembre
A8: RESIDENCIAL
A9: T-RE
A10: Primeros 200 KWh | B10: 71 | C10: 71 | D10: 71 | E10: 79.866667 | F10: 80 | G10: 80 | H10: 75 | I10: 75 | J10: 79.666667 | K10: 77 | L10: 77 | M10: 77
A11: kWh adicional | B11: 123 | C11: 123 | D11: 123 | E11: 136.8 | F11: 137 | G11: 137 | H11: 129 | I11: 129 | J11: 133.2 | K11: 124 | L11: 124 | M11: 124
A12: GENERAL
A13: T-GE
A14: Energía_Bloq. ≤3.000 KWh | B14: 141 | C14: 141 | D14: 141 | E14: 158 | F14: 158 | G14: 158 | H14: 149 | I14: 149 | J14: 156.46667 | K14: 149 | L14: 149 | M14: 149
A15: Energía_Bloq. >3.000 KWh (primeros 3000 KWh) | B15: 252000 | C15: 252000 | D15: 252000 | E15: 284600 | F15: 285000 | G15: 285000 | H15: 270000 | I15: 270000 | J15: 284000 | K15: 270000 | L15: 270000 | M15: 270000
A16: Energía_Bloq. >3.000 KWh (KWh adicional) | B16: 84 | C16: 84 | D16: 84 | E16: 94.866667 | F16: 95 | G16: 95 | H16: 90 | I16: 90 | J16: 94.666667 | K16: 90 | L16: 90 | M16: 90
A17: Potencia_Menor igual al diferencial (mínimo) | B17: 209355 | C17: 209355 | D17: 209355 | E17: 234370 | F17: 234705 | G17: 234705 | H17: 221370 | I17: 221370 | J17: 232633 | K17: 221130 | L17: 221130 | M17: 221130
A18: Potencia_Mayor al diferencial (adicional) | B18: 13957 | C18: 13957 | D18: 13957 | E18: 15624.667 | F18: 15647 | G18: 15647 | H18: 14758 | I18: 14758 | J18: 15508.867 | K18: 14742 | L18: 14742 | M18: 14742
A19: PREFERENCIAL
A20: T-CS
A21: Energía_Bloq. ≤ 250 KWh | B21: 111 | C21: 111 | D21: 111 | E21: 125 | F21: 125 | G21: 125 | H21: 118 | I21: 118 | J21: 118 | K21: 106 | L21: 106 | M21: 106
A22: Energía_Bloq. De 251 a 3.000 KWh | B22: 141 | C22: 141 | D22: 141 | E22: 158 | F22: 158 | G22: 158 | H22: 149 | I22: 149 | J22: 149 | K22: 149 | L22: 149 | M22: 149
A23: Energía_Bloq. >3.000 KWh (primeros 3000 KWh) | B23: 252000 | C23: 252000 | D23: 252000 | E23: 285000 | F23: 285000 | G23: 285000 | H23: 270000 | I23: 270000 | J23: 284000 | K23: 270000 | L23: 270000 | M23: 270000
A24: Energía_Bloq. >3.000 KWh (KWh adicional) | B24: 84 | C24: 84 | D24: 84 | E24: 95 | F24: 95 | G24: 95 | H24: 90 | I24: 90 | J24: 94.666667 | K24: 90 | L24: 90 | M24: 90
A25: Potencia_Menor igual al diferencial (mínimo) | B25: 209355 | C25: 209355 | D25: 209355 | E25: 234705 | F25: 234705 | G25: 234705 | H25: 221370 | I25: 221370 | J25: 232633 | K25: 221130 | L25: 221130 | M25: 221130
A26: Potencia_Mayor al diferencial (adicional) | B26: 13957 | C26: 13957 | D26: 13957 | E26: 15647 | F26: 15647 | G26: 15647 | H26: 14758 | I26: 14758 | J26: 15508.867 | K26: 14742 | L26: 14742 | M26: 14742
A27: MEDIA TENSIÓN (T-MT)
A28: T-MT
A29: Energía_Punta | B29: 64 | C29: 64 | D29: 64 | E29: 71.866667 | F29: 72 | G29: 72 | H29: 67 | I29: 67 | J29: 72.6 | K29: 71 | L29: 71 | M29: 71
A30: Energía_Valle | B30: 27 | C30: 27 | D30: 27 | E30: 29.933333 | F30: 30 | G30: 30 | H30: 28 | I30: 28 | J30: 29.4 | K30: 28 | L30: 28 | M30: 28
A31: Energía_Noche | B31: 16 | C31: 16 | D31: 16 | E31: 18 | F31: 18 | G31: 18 | H31: 18 | I31: 18 | J31: 18.933333 | K31: 18 | L31: 18 | M31: 18
A32: Potencia_Punta | B32: 10326 | C32: 10326 | D32: 10326 | E32: 11559.467 | F32: 11576 | G32: 11576 | H32: 10918 | I32: 10918 | J32: 11427.133 | K32: 10817 | L32: 10817 | M32: 10817
A33: Potencia_Valle | B33: 7405 | C33: 7405 | D33: 7405 | E33: 8290.1333 | F33: 8302 | G33: 8302 | H33: 7829 | I33: 7829 | J33: 8194.4 | K33: 7756 | L33: 7756 | M33: 7756
A34: Potencia_Noche | B34: 4722 | C34: 4722 | D34: 4722 | E34: 5285.4667 | F34: 5293 | G34: 5293 | H34: 4992 | I34: 4992 | J34: 5225.3333 | K34: 4947 | L34: 4947 | M34: 4947
A35: ALUMBRADO PÚBLICO
A36: T-AP
A37: Cada KWh | B37: 3.72 | C37: 3.72 | D37: 3.72 | E37: 3.72 | F37: 3.72 | G37: 3.72 | H37: 3.72 | I37: 3.72 | J37: 3.72 | K37: 3.72 | L37: 3.72 | M37: 3.72

Sheet CAR 2013
A5: Tabla 9
A6: Tarifas del servicio de distribución eléctrica y alumbrado público prestado por CoopeAlfaroRuiz R.L para el año 2013, según el mes y el tipo de tarifa respectivo.
A7: Tipo de tarifa y bloque | B7: Enero | C7: Febrero | D7: Marzo | E7: Abril | F7: Mayo | G7: Junio | H7: Julio | I7: Agosto | J7: Septiembre | K7: Octubre | L7: Noviembre | M7: Diciembre
A8: RESIDENCIAL
A9: T-RE
A10: Primeros 200 KWh | B10: 72 | C10: 72 | D10: 72 | E10: 77.933333 | F10: 78 | G10: 78 | H10: 75 | I10: 75 | J10: 75 | K10: 65 | L10: 63 | M10: 63
A11: kWh adicional | B11: 93 | C11: 93 | D11: 93 | E11: 100.93333 | F11: 101 | G11: 101 | H11: 97 | I11: 97 | J11: 97 | K11: 84 | L11: 82 | M11: 82
A12: GENERAL
A13: T-GE
A14: Energía_Bloq. ≤3.000 KWh | B14: 100 | C14: 100 | D14: 100 | E14: 107.93333 | F14: 108 | G14: 108 | H14: 105 | I14: 105 | J14: 105 | K14: 91 | L14: 88 | M14: 88
A15: Energía_Bloq. >3.000 KWh (primeros 3000 KWh) | B15: 180000 | C15: 180000 | D15: 180000 | E15: 198000 | F15: 198000 | G15: 198000 | H15: 189000 | I15: 189000 | J15: 189000 | K15: 165000 | L15: 162000 | M15: 162000
A16: Energía_Bloq. >3.000 KWh (KWh adicional) | B16: 60 | C16: 60 | D16: 60 | E16: 66 | F16: 66 | G16: 66 | H16: 63 | I16: 63 | J16: 63 | K16: 55 | L16: 54 | M16: 54
A17: Potencia_Menor igual al diferencial (mínimo) | B17: 141990 | C17: 141990 | D17: 141990 | E17: 103040 | F17: 103040 | G17: 103040 | H17: 149445 | I17: 149445 | J17: 149445 | K17: 129240 | L17: 125925 | M17: 125925
A18: Potencia_Mayor al diferencial (adicional) | B18: 9466 | C18: 9466 | D18: 9466 | E18: 10304 | F18: 10304 | G18: 10304 | H18: 9963 | I18: 9963 | J18: 9963 | K18: 8616 | L18: 8395 | M18: 8395
A19: ALUMBRADO PÚBLICO
A20: T-AP
A21: Cada KWh | B21: 3.18 | C21: 3.18 | D21: 3.18 | E21: 3.18 | F21: 3.18 | G21: 3.18 | H21: 3.18 | I21: 3.18 | J21: 3.18 | K21: 3.18 | L21: 3.18 | M21: 3.18

Sheet 2014
B2: Seleccione la empresa que desea consultar:

Sheet ICE 2014
A5: Tabla 1
A6: Tarifas del servicio de generación eléctrica prestado por el ICE para el año 2014, según el mes y el tipo de tarifa respectivo.
A7: Tipo de tarifa y bloque | B7: Enero | C7: Febrero | D7: Marzo | E7: Abril | F7: Mayo | G7: Junio | H7: Julio | I7: Agosto | J7: Septiembre | K7: Octubre | L7: Noviembre | M7: Diciembre
A8: Ventas a ICE distribución y a la CNFL
A9: T-CB
A10: Energía_Punta | B10: 51.5 | C10: 51.5 | D10: 51.5 | E10: 58 | F10: 58 | G10: 58 | H10: 63 | I10: 63 | J10: 63 | K10: 58.9 | L10: 58.9 | M10: 58.9
A11: Energía_Valle | B11: 42.2 | C11: 42.2 | D11: 42.2 | E11: 47 | F11: 47 | G11: 47 | H11: 51 | I11: 51 | J11: 51 | K11: 48.2 | L11: 48.2 | M11: 48.2
A12: Energía_Noche | B12: 35.8 | C12: 35.8 | D12: 35.8 | E12: 40 | F12: 40 | G12: 40 | H12: 44 | I12: 44 | J12: 44 | K12: 41 | L12: 41 | M12: 41
A13: Potencia_Punta | B13: 2731 | C13: 2731 | D13: 2731 | E13: 3057 | F13: 3057 | G13: 3057 | H13: 3327 | I13: 3327 | J13: 3327 | K13: 3122 | L13: 3122 | M13: 3122
A14: Potencia_Valle | B14: 2731 | C14: 2731 | D14: 2731 | E14: 3057 | F14: 3057 | G14: 3057 | H14: 3327 | I14: 3327 | J14: 3327 | K14: 3122 | L14: 3122 | M14: 3122
A15: VENTAS AL SERVICIO DE DISTRIBUCIÓN
A16: T-SD
A17: Energía_Punta | B17: 50.8 | C17: 50.8 | D17: 50.8 | E17: 56.9 | F17: 56.9 | G17: 56.9 | H17: 61.9 | I17: 61.9 | J17: 61.9 | K17: 58.1 | L17: 58.1 | M17: 58.1
A18: Energía_Valle | B18: 41.7 | C18: 41.7 | D18: 41.7 | E18: 46.7 | F18: 46.7 | G18: 46.7 | H18: 50.8 | I18: 50.8 | J18: 50.8 | K18: 47.6 | L18: 47.6 | M18: 47.6
A19: Energía_Noche | B19: 35.6 | C19: 35.6 | D19: 35.6 | E19: 39.8 | F19: 39.8 | G19: 39.8 | H19: 43.3 | I19: 43.3 | J19: 43.3 | K19: 40.7 | L19: 40.7 | M19: 40.7
A20: Potencia_Punta | B20: 2731 | C20: 2731 | D20: 2731 | E20: 3057 | F20: 3057 | G20: 3057 | H20: 3327 | I20: 3327 | J20: 3327 | K20: 3122 | L20: 3122 | M20: 3122
A21: Potencia_Valle | B21: 2731 | C21: 2731 | D21: 2731 | E21: 3057 | F21: 3057 | G21: 3057 | H21: 3327 | I21: 3327 | J21: 3327 | K21: 3122 | L21: 3122 | M21: 3122
A22: USUARIOS DIRECTOS
A23: T-UD
A24: Energía_Punta | B24: 0.062 | C24: 0.062 | D24: 0.062 | E24: 0.064 | F24: 0.064 | G24: 0.064 | H24: 0.058 | I24: 0.058 | J24: 0.058 | K24: 0.059 | L24: 0.059 | M24: 0.059
A25: Energía_Valle | B25: 0.051 | C25: 0.051 | D25: 0.051 | E25: 0.053 | F25: 0.053 | G25: 0.053 | H25: 0.047 | I25: 0.047 | J25: 0.047 | K25: 0.049 | L25: 0.049 | M25: 0.049
A26: Energía_Noche | B26: 0.044 | C26: 0.044 | D26: 0.044 | E26: 0.045 | F26: 0.045 | G26: 0.045 | H26: 0.041 | I26: 0.041 | J26: 0.041 | K26: 0.042 | L26: 0.042 | M26: 0.042
A27: Potencia_Punta | B27: 3.29 | C27: 3.29 | D27: 3.29 | E27: 3.41 | F27: 3.41 | G27: 3.41 | H27: 3.06 | I27: 3.06 | J27: 3.06 | K27: 3.13 | L27: 3.13 | M27: 3.13
A28: Potencia_Valle | B28: 3.29 | C28: 3.29 | D28: 3.29 | E28: 3.41 | F28: 3.41 | G28: 3.41 | H28: 3.06 | I28: 3.06 | J28: 3.06 | K28: 3.13 | L28: 3.13 | M28: 3.13
A29: Fuente: Autoridad Reguladora de los Servicios Públicos
A30: * Las tarifas pueden diferir del valor puntual de los pliegos pues la tabla muestra el promedio del mes, y de existir dos o más tarifas que estuvieron vigentes, se realiza un promedio ponderado por la cantidad de días.
A38: Tabla 2
A39: Tarifas del servicio de distribución eléctrica y alumbrado público prestado por el ICE para el año 2014, según el mes y el tipo de tarifa respectivo.
A40: Tipo de tarifa y bloque | C40: Febrero | D40: Marzo | E40: Abril | F40: Mayo | G40: Junio | H40: Julio | I40: Agosto | J40: Septiembre | K40: Octubre | L40: Noviembre | M40: Diciembre
A41: RESIDENCIAL
A42: T-RE
A43: Primeros 200 KWh | B43: 81 | C43: 81 | D43: 81 | E43: 87 | F43: 87 | G43: 87 | H43: 91 | I43: 91 | J43: 91 | K43: 88 | L43: 88 | M43: 88
A44: De 201 a 300 KWh | B44: 128 | C44: 128 | D44: 128 | E44: 128 | F44: 128 | G44: 128 | H44: 128 | I44: 128 | J44: 128 | K44: 128 | L44: 128 | M44: 128
A45: kWh adicional | B45: 146 | C45: 146 | D45: 146 | E45: 156 | F45: 156 | G45: 156 | H45: 164 | I45: 164 | J45: 164 | K45: 159 | L45: 159 | M45: 159
A46: GENERAL
A47: T-GE
A48: Energía_Bloq. ≤3.000 KWh | B48: 122 | C48: 122 | D48: 122 | E48: 130 | F48: 130 | G48: 130 | H48: 137 | I48: 137 | J48: 137 | K48: 132 | L48: 132 | M48: 132
A49: Energía_Bloq. >3.000 KWh (KWh adicional) | B49: 73 | C49: 73 | D49: 73 | E49: 78 | F49: 78 | G49: 78 | H49: 82 | I49: 82 | J49: 82 | K49: 79 | L49: 79 | M49: 79
A50: Potencia_Mayor al diferencial (adicional) | B50: 12086 | C50: 12086 | D50: 12086 | E50: 12917 | F50: 12917 | G50: 12917 | H50: 13604 | I50: 13604 | J50: 13604 | K50: 13094 | L50: 13094 | M50: 13094
A51: PREFERENCIAL
...

Sheet CNFL 2014
A3: Tabla 3
A4: Tarifas del servicio de distribución eléctrica y alumbrado público prestado por la CNFL para el año 2014, según el mes y el tipo de tarifa respectivo.
A5: Tipo de tarifa y bloque | B5: Enero | C5: Febrero | D5: Marzo | E5: Abril | F5: Mayo | G5: Junio | H5: Julio | I5: Agosto | J5: Septiembre | K5: Octubre | L5: Noviembre | M5: Diciembre
A6: RESIDENCIAL
A7: T-RE
A8: Primeros 200 KWh | B8: 67 | C8: 67 | D8: 67 | E8: 72 | F8: 72 | G8: 72 | H8: 75 | I8: 75 | J8: 75 | K8: 69 | L8: 69 | M8: 69
A9: De 201 a 300 KWh | B9: 102 | C9: 102 | D9: 102 | E9: 110 | F9: 110 | G9: 110 | H9: 114 | I9: 114 | J9: 114 | K9: 106 | L9: 106 | M9: 106
A10: kWh adicional | B10: 106 | C10: 106 | D10: 106 | E10: 113 | F10: 113 | G10: 113 | H10: 118 | I10: 118 | J10: 118 | K10: 110 | L10: 110 | M10: 110
A11: GENERAL
A12: T-GE
A13: Energía_Bloq. ≤3.000 KWh | B13: 113 | C13: 113 | D13: 113 | E13: 121 | F13: 121 | G13: 121 | H13: 126 | I13: 126 | J13: 126 | K13: 117 | L13: 117 | M13: 117
A14: Energía_Bloq. >3.000 KWh (primeros 3000 KWh) | B14: 204000 | C14: 204000 | D14: 204000 | E14: 219000 | F14: 219000 | G14: 219000 | H14: 228000 | I14: 228000 | J14: 228000 | K14: 213000 | L14: 213000 | M14: 213000
A15: Energía_Bloq. >3.000 KWh (KWh adicional) | B15: 68 | C15: 68 | D15: 68 | E15: 73 | F15: 73 | G15: 73 | H15: 76 | I15: 76 | J15: 76 | K15: 71 | L15: 71 | M15: 71
A16: Potencia_Menor igual al diferencial (mínimo) | B16: 84856 | C16: 84856 | D16: 84856 | E16: 91088 | F16: 91088 | G16: 91088 | H16: 95032 | I16: 95032 | J16: 95032 | K16: 88400 | L16: 88400 | M16: 88400
A17: Potencia_Mayor al diferencial (adicional) | B17: 10607 | C17: 10607 | D17: 10607 | E17: 11386 | F17: 11386 | G17: 11386 | H17: 11879 | I17: 11879 | J17: 11879 | K17: 11050 | L17: 11050 | M17: 11050
A18: PREFERENCIAL
A19: T-CS
A20: Energía_Bloq. ≤3.000 KWh | B20: 76 | C20: 76 | D20: 76 | E20: 81 | F20: 81 | G20: 81 | H20: 85 | I20: 85 | J20: 85 | K20: 79 | L20: 79 | M20: 79
A21: Energía_Bloq. >3.000 KWh (primeros 3000 KWh) | B21: 132000 | C21: 132000 | D21: 132000 | E21: 141000 | F21: 141000 | G21: 141000 | H21: 147000 | I21: 147000 | J21: 147000 | K21: 135000 | L21: 135000 | M21: 135000
A22: Energía_Bloq. >3.000 KWh (KWh adicional) | B22: 44 | C22: 44 | D22: 44 | E22: 47 | F22: 47 | G22: 47 | H22: 49 | I22: 49 | J22: 49 | K22: 45 | L22: 45 | M22: 45
A23: Potencia_Menor igual al diferencial (mínimo) | B23: 56528 | C23: 56528 | D23: 56528 | E23: 60680 | F23: 60680 | G23: 60680 | H23: 63312 | I23: 63312 | J23: 63312 | K23: 58896 | L23: 58896 | M23: 58896
A24: Potencia_Mayor al diferencial (adicional) | B24: 7066 | C24: 7066 | D24: 7066 | E24: 7585 | F24: 7585 | G24: 7585 | H24: 7914 | I24: 7914 | J24: 7914 | K24: 7362 | L24: 7362 | M24: 7362
A25: MEDIA TENSIÓN (T-MT)
A26: T-MT
A27: Energía_Punta | B27: 57 | C27: 57 | D27: 57 | E27: 62 | F27: 62 | G27: 62 | H27: 64 | I27: 64 | J27: 64 | K27: 60 | L27: 60 | M27: 60
A28: Energía_Valle | B28: 29 | C28: 29 | D28: 29 | E28: 31 | F28: 31 | G28: 31 | H28: 32 | I28: 32 | J28: 32 | K28: 30 | L28: 30 | M28: 30
A29: Energía_Noche | B29: 21 | C29: 21 | D29: 21 | E29: 22 | F29: 22 | G29: 22 | H29: 23 | I29: 23 | J29: 23 | K29: 22 | L29: 22 | M29: 22
A30: Potencia_Punta | B30: 10068 | C30: 10068 | D30: 10068 | E30: 10808 | F30: 10808 | G30: 10808 | H30: 11276 | I30: 11276 | J30: 11276 | K30: 10489 | L30: 10489 | M30: 10489
A31: Potencia_Valle | B31: 7164 | C31: 7164 | D31: 7164 | E31: 7690 | F31: 7690 | G31: 7690 | H31: 8023 | I31: 8023 | J31: 8023 | K31: 7463 | L31: 7463 | M31: 7463
A32: Potencia_Noche | B32: 4548 | C32: 4548 | D32: 4548 | E32: 4882 | F32: 4882 | G32: 4882 | H32: 5093 | I32: 5093 | J32: 5093 | K32: 4738 | L32: 4738 | M32: 4738
A33: Residencial horaria
A34: T-REH
A35: Bloque 0-300 KWh Punta | B35: 141 | C35: 141 | D35: 141 | E35: 152 | F35: 152 | G35: 152 | H35: 158 | I35: 158 | J35: 158 | K35: 147 | L35: 147 | M35: 147
A36: Bloque 0-300 KWh Valle | B36: 59 | C36: 59 | D36: 59 | E36: 63 | F36: 63 | G36: 63 | H36: 66 | I36: 66 | J36: 66 | K36: 61 | L36: 61 | M36: 61
A37: Bloque 0-300 KWh Noche | B37: 24 | C37: 24 | D37: 24 | E37: 26 | F37: 26 | G37: 26 | H37: 27 | I37: 27 | J37: 27 | K37: 25 | L37: 25 | M37: 25
A38: Bloque 301-500 KWh Punta | B38: 161 | C38: 161 | D38: 161 | E38: 173 | F38: 173 | G38: 173 | H38: 180 | I38: 180 | J38: 180 | K38: 167 | L38: 167 | M38: 167
A39: Bloque 301-500 KWh Valle | B39: 65 | C39: 65 | D39: 65 | E39: 70 | F39: 70 | G39: 70 | H39: 73 | I39: 73 | J39: 73 | K39: 68 | L39: 68 | M39: 68
A40: Bloque 301-500 KWh Noche | B40: 28 | C40: 28 | D40: 28 | E40: 30 | F40: 30 | G40: 30 | H40: 31 | I40: 31 | J40: 31 | K40: 29 | L40: 29 | M40: 29
A41: Bloque más de 500 KWh Punta | B41: 191 | C41: 191 | D41: 191 | E41: 205 | F41: 205 | G41: 205 | H41: 214 | I41: 214 | J41: 214 | K41: 199 | L41: 199 | M41: 199
A42: Bloque más de 500 KWh Valle | B42: 77 | C42: 77 | D42: 77 | E42: 83 | F42: 83 | G42: 83 | H42: 86 | I42: 86 | J42: 86 | K42: 80 | L42: 80 | M42: 80
...

Sheet JASEC 2014
A4: Tabla 4
A5: Tarifas del servicio de distribución eléctrica y alumbrado público prestado por JASEC para el año 2014, según el mes y el tipo de tarifa respectivo.
A6: Tipo de tarifa y bloque | B6: Enero | C6: Febrero | D6: Marzo | E6: Abril | F6: Mayo | G6: Junio | H6: Julio | I6: Agosto | J6: Septiembre | K6: Octubre | L6: Noviembre | M6: Diciembre
A7: RESIDENCIAL
A8: T-RE
A9: Primeros 200 KWh | B9: 65 | C9: 65 | D9: 65 | E9: 71 | F9: 71 | G9: 71 | H9: 73 | I9: 73 | J9: 73 | K9: 69 | L9: 69 | M9: 69
A10: kWh adicional | B10: 80 | C10: 80 | D10: 80 | E10: 87 | F10: 87 | G10: 87 | H10: 89 | I10: 89 | J10: 89 | K10: 85 | L10: 85 | M10: 85
A11: GENERAL
A12: T-GE
A13: Energía_Bloq. ≤3.000 KWh | B13: 92 | C13: 92 | D13: 92 | E13: 101 | F13: 101 | G13: 101 | H13: 103 | I13: 103 | J13: 103 | K13: 98 | L13: 98 | M13: 98
A14: Energía_Bloq. >3.000 KWh (primeros 3000 KWh) | B14: 165000 | C14: 165000 | D14: 165000 | E14: 180000 | F14: 180000 | G14: 180000 | H14: 186000 | I14: 186000 | J14: 186000 | K14: 174000 | L14: 174000 | M14: 174000
A15: Energía_Bloq. >3.000 KWh (KWh adicional) | B15: 55 | C15: 55 | D15: 55 | E15: 60 | F15: 60 | G15: 60 | H15: 62 | I15: 62 | J15: 62 | K15: 58 | L15: 58 | M15: 58
A16: Potencia_Menor igual al diferencial (mínimo) | B16: 69144 | C16: 69144 | D16: 69144 | E16: 75216 | F16: 75216 | G16: 75216 | H16: 77256 | I16: 77256 | J16: 77256 | K16: 73000 | L16: 73000 | M16: 73000
A17: Potencia_Mayor al diferencial (adicional) | B17: 8643 | C17: 8643 | D17: 8643 | E17: 9402 | F17: 9402 | G17: 9402 | H17: 9657 | I17: 9657 | J17: 9657 | K17: 9125 | L17: 9125 | M17: 9125
A18: PREFERENCIAL
A19: T-CS
A20: Energía_Bloq. ≤3.000 KWh | B20: 67 | C20: 67 | D20: 67 | E20: 72 | F20: 72 | G20: 72 | H20: 74 | I20: 74 | J20: 74 | K20: 70 | L20: 70 | M20: 70
A21: Energía_Bloq. >3.000 KWh (primeros 3000 KWh) | B21: 114000 | C21: 114000 | D21: 114000 | E21: 126000 | F21: 126000 | G21: 126000 | H21: 129000 | I21: 129000 | J21: 129000 | K21: 120000 | L21: 120000 | M21: 120000
A22: Energía_Bloq. >3.000 KWh (KWh adicional) | B22: 38 | C22: 38 | D22: 38 | E22: 42 | F22: 42 | G22: 42 | H22: 43 | I22: 43 | J22: 43 | K22: 40 | L22: 40 | M22: 40
A23: Potencia_Menor igual al diferencial (mínimo) | B23: 46464 | C23: 46464 | D23: 46464 | E23: 50552 | F23: 50552 | G23: 50552 | H23: 51920 | I23: 51920 | J23: 51920 | K23: 49056 | L23: 49056 | M23: 49056
A24: Potencia_Mayor al diferencial (adicional) | B24: 5808 | C24: 5808 | D24: 5808 | E24: 6319 | F24: 6319 | G24: 6319 | H24: 6490 | I24: 6490 | J24: 6490 | K24: 6132 | L24: 6132 | M24: 6132
A25: MEDIA TENSIÓN (T-MT)
A26: T-MT
A27: Energía_Punta | B27: 51 | C27: 51 | D27: 51 | E27: 55 | F27: 55 | G27: 55 | H27: 57 | I27: 57 | J27: 57 | K27: 54 | L27: 54 | M27: 54
A28: Energía_Valle | B28: 25 | C28: 25 | D28: 25 | E28: 27 | F28: 27 | G28: 27 | H28: 28 | I28: 28 | J28: 28 | K28: 26 | L28: 26 | M28: 26
A29: Energía_Noche | B29: 17 | C29: 17 | D29: 17 | E29: 18 | F29: 18 | G29: 18 | H29: 19 | I29: 19 | J29: 19 | K29: 18 | L29: 18 | M29: 18
A30: Potencia_Punta | B30: 8929 | C30: 8929 | D30: 8929 | E30: 9714 | F30: 9714 | G30: 9714 | H30: 9977 | I30: 9977 | J30: 9977 | K30: 9427 | L30: 9427 | M30: 9427
A31: Potencia_Valle | B31: 6403 | C31: 6403 | D31: 6403 | E31: 6965 | F31: 6965 | G31: 6965 | H31: 7154 | I31: 7154 | J31: 7154 | K31: 6760 | L31: 6760 | M31: 6760
A32: Potencia_Noche | B32: 4380 | C32: 4380 | D32: 4380 | E32: 4765 | F32: 4765 | G32: 4765 | H32: 4894 | I32: 4894 | J32: 4894 | K32: 4624 | L32: 4624 | M32: 4624
A33: ALUMBRADO PÚBLICO
A34: T-AP
A35: Cada KWh | B35: 3.06 | C35: 3.06 | D35: 3.06 | E35: 3.06 | F35: 3.06 | G35: 3.06 | H35: 3.06 | I35: 3.06 | J35: 3.06 | K35: 3.06 | L35: 3.06 | M35: 3.06

Sheet ESPH 2014
A5: Tabla 5
A6: Tarifas del servicio de distribución eléctrica y alumbrado público prestado por ESPH para el año 2014, según el mes y el tipo de tarifa respectivo.
A7: Tipo de tarifa y bloque | B7: Enero | C7: Febrero | D7: Marzo | E7: Abril | F7: Mayo | G7: Junio | H7: Julio | I7: Agosto | J7: Septiembre | K7: Octubre | L7: Noviembre | M7: Diciembre
A8: RESIDENCIAL
A9: T-RE
A10: Primeros 200 KWh | B10: 67 | C10: 67 | D10: 67 | E10: 73 | F10: 73 | G10: 73 | H10: 74 | I10: 74 | J10: 74 | K10: 69 | L10: 69 | M10: 69
A11: kWh adicional | B11: 87 | C11: 87 | D11: 87 | E11: 94 | F11: 94 | G11: 94 | H11: 96 | I11: 96 | J11: 96 | K11: 90 | L11: 90 | M11: 90
A12: GENERAL
A13: T-GE
A14: Energía_Bloq. ≤3.000 KWh | B14: 92 | C14: 92 | D14: 92 | E14: 100 | F14: 100 | G14: 100 | H14: 103 | I14: 103 | J14: 103 | K14: 96 | L14: 96 | M14: 96
A15: Energía_Bloq. >3.000 KWh (primeros 3000 KWh) | B15: 156000 | C15: 156000 | D15: 156000 | E15: 168000 | F15: 168000 | G15: 168000 | H15: 174000 | I15: 174000 | J15: 174000 | K15: 162000 | L15: 162000 | M15: 162000
A16: Energía_Bloq. >3.000 KWh (KWh adicional) | B16: 52 | C16: 52 | D16: 52 | E16: 56 | F16: 56 | G16: 56 | H16: 58 | I16: 58 | J16: 58 | K16: 54 | L16: 54 | M16: 54
A17: Potencia_Menor igual al diferencial (mínimo) | B17: 84360 | C17: 84360 | D17: 84360 | E17: 91660 | F17: 91660 | G17: 91660 | H17: 93620 | I17: 93620 | J17: 93620 | K17: 87530 | L17: 87530 | M17: 87530
A18: Potencia_Mayor al diferencial (adicional) | B18: 8436 | C18: 8436 | D18: 8436 | E18: 9166 | F18: 9166 | G18: 9166 | H18: 9362 | I18: 9362 | J18: 9362 | K18: 8753 | L18: 8753 | M18: 8753
A19: PREFERENCIAL
A20: T-CS
A21: Energía_Bloq. ≤3.000 KWh | B21: 67 | C21: 67 | D21: 67 | E21: 73 | F21: 73 | G21: 73 | H21: 74 | I21: 74 | J21: 74 | K21: 69 | L21: 69 | M21: 69
A22: Energía_Bloq. >3.000 KWh (primeros 3000 KWh) | B22: 138000 | C22: 138000 | D22: 138000 | E22: 150000 | F22: 150000 | G22: 150000 | H22: 153000 | I22: 153000 | J22: 153000 | K22: 144000 | L22: 144000 | M22: 144000
A23: Energía_Bloq. >3.000 KWh (KWh adicional) | B23: 46 | C23: 46 | D23: 46 | E23: 50 | F23: 50 | G23: 50 | H23: 51 | I23: 51 | J23: 51 | K23: 48 | L23: 48 | M23: 48
A24: Potencia_Menor igual al diferencial (mínimo) | B24: 72080 | C24: 72080 | D24: 72080 | E24: 78320 | F24: 78320 | G24: 78320 | H24: 79990 | I24: 79990 | J24: 79990 | K24: 74790 | L24: 74790 | M24: 74790
A25: Potencia_Mayor al diferencial (adicional) | B25: 7208 | C25: 7208 | D25: 7208 | E25: 7832 | F25: 7832 | G25: 7832 | H25: 7999 | I25: 7999 | J25: 7999 | K25: 7479 | L25: 7479 | M25: 7479
A26: MEDIA TENSIÓN (T-MT)
A27: T-MT
A28: Energía_Punta | B28: 61 | C28: 61 | D28: 61 | E28: 66 | F28: 66 | G28: 66 | H28: 68 | I28: 68 | J28: 68 | K28: 63 | L28: 63 | M28: 63
A29: Energía_Valle | B29: 31 | C29: 31 | D29: 31 | E29: 34 | F29: 34 | G29: 34 | H29: 35 | I29: 35 | J29: 35 | K29: 32 | L29: 32 | M29: 32
A30: Energía_Noche | B30: 25 | C30: 25 | D30: 25 | E30: 28 | F30: 28 | G30: 28 | H30: 28 | I30: 28 | J30: 28 | K30: 26 | L30: 26 | M30: 26
A31: Potencia_Punta | B31: 10252 | C31: 10252 | D31: 10252 | E31: 11140 | F31: 11140 | G31: 11140 | H31: 11378 | I31: 11378 | J31: 11378 | K31: 10637 | L31: 10637 | M31: 10637
A32: Potencia_Valle | B32: 7123 | C32: 7123 | D32: 7123 | E32: 7740 | F32: 7740 | G32: 7740 | H32: 7906 | I32: 7906 | J32: 7906 | K32: 7391 | L32: 7391 | M32: 7391
A33: Potencia_Noche | B33: 4747 | C33: 4747 | D33: 4747 | E33: 5158 | F33: 5158 | G33: 5158 | H33: 5269 | I33: 5269 | J33: 5269 | K33: 4926 | L33: 4926 | M33: 4926
A34: ALUMBRADO PÚBLICO
A35: T-AP
A36: Cada KWh | B36: 3.05 | C36: 3.05 | D36: 3.05 | E36: 3.05 | F36: 3.05 | G36: 3.05 | H36: 3.05 | I36: 3.05 | J36: 3.05 | K36: 3.05 | L36: 3.05 | M36: 3.05

Sheet CL 2014
A5: Tabla 6
A6: Tarifas del servicio de distribución eléctrica y alumbrado público prestado por Coopelesca R.L para el año 2014, según el mes y el tipo de tarifa respectivo.
A7: Tipo de tarifa y bloque | B7: Enero | C7: Febrero | D7: Marzo | E7: Abril | F7: Mayo | G7: Junio | H7: Julio | I7: Agosto | J7: Septiembre | K7: Octubre | L7: Noviembre | M7: Diciembre
A8: RESIDENCIAL
A9: T-RE
A10: Primeros 200 KWh | B10: 82 | C10: 82 | D10: 82 | E10: 86 | F10: 86 | G10: 86 | H10: 81 | I10: 77.516129 | J10: 75 | K10: 73 | L10: 73.866667 | M10: 74
A11: kWh adicional | B11: 101 | C11: 101 | D11: 101 | E11: 106 | F11: 106 | G11: 106 | H11: 101 | I11: 96.354839 | J11: 93 | K11: 91 | L11: 92.733333 | M11: 93
A12: GENERAL
A13: T-GE
A14: Energía_Bloq. ≤3.000 KWh | B14: 107 | C14: 107 | D14: 107 | E14: 112 | F14: 112 | G14: 112 | H14: 106 | I14: 100.77419 | J14: 97 | K14: 95 | L14: 96.733333 | M14: 97
A15: Energía_Bloq. >3.000 KWh (primeros 3000 KWh) | B15: 258000 | C15: 258000 | D15: 258000 | E15: 273000 | F15: 273000 | G15: 273000 | H15: 258000 | I15: 245806.45 | J15: 237000 | K15: 234000 | L15: 236600 | M15: 237000
A16: Energía_Bloq. >3.000 KWh (KWh adicional) | B16: 86 | C16: 86 | D16: 86 | E16: 91 | F16: 91 | G16: 91 | H16: 86 | I16: 81.935484 | J16: 79 | K16: 78 | L16: 78.866667 | M16: 79
A17: Potencia_Menor igual al diferencial (mínimo) | B17: 52260 | C17: 52260 | D17: 52260 | E17: 54980 | F17: 54980 | G17: 54980 | H17: 51960 | I17: 49531.161 | J17: 47777 | K17: 46780 | L17: 47551.333 | M17: 47670
A18: Potencia_Mayor al diferencial (adicional) | B18: 5226 | C18: 5226 | D18: 5226 | E18: 5498 | F18: 5498 | G18: 5498 | H18: 5196 | I18: 4952.7097 | J18: 4777 | K18: 4678 | L18: 4755.1333 | M18: 4767
A19: MEDIA TENSIÓN (T-MT)
A20: T-MT
A21: Energía_Punta | B21: 85 | C21: 85 | D21: 85 | E21: 89 | F21: 89 | G21: 89 | H21: 85 | I21: 80.935484 | J21: 78 | K21: 77 | L21: 77.866667 | M21: 78
A22: Energía_Valle | B22: 72 | C22: 72 | D22: 72 | E22: 76 | F22: 76 | G22: 76 | H22: 72 | I22: 67.935484 | J22: 65 | K22: 64 | L22: 64.866667 | M22: 65
A23: Energía_Noche | B23: 65 | C23: 65 | D23: 65 | E23: 68 | F23: 68 | G23: 68 | H23: 64 | I23: 61.096774 | J23: 59 | K23: 58 | L23: 58.866667 | M23: 59
A24: Potencia_Punta | B24: 4897 | C24: 4897 | D24: 4897 | E24: 5152 | F24: 5152 | G24: 5152 | H24: 4869 | I24: 4641.3871 | J24: 4477 | K24: 4384 | L24: 4455.9333 | M24: 4467
A25: Potencia_Valle | B25: 4897 | C25: 4897 | D25: 4897 | E25: 5152 | F25: 5152 | G25: 5152 | H25: 4869 | I25: 4641.3871 | J25: 4477 | K25: 4384 | L25: 4455.9333 | M25: 4467
A26: ALUMBRADO PÚBLICO
A27: T-AP
A28: Cada KWh | B28: 4.01 | C28: 4.01 | D28: 4.01 | E28: 4.01 | F28: 4.01 | G28: 4.01 | H28: 4.01 | I28: 4.01 | J28: 4.01 | K28: 4.01 | L28: 4.01 | M28: 4.01

Sheet CG 2014
A5: Tabla 7
A6: Tarifas del servicio de distribución eléctrica y alumbrado público prestado por CoopeGuanacaste R.L para el año 2014, según el mes y el tipo de tarifa respectivo.
A7: Tipo de tarifa y bloque | B7: Enero | C7: Febrero | D7: Marzo | E7: Abril | F7: Mayo | G7: Junio | H7: Julio | I7: Agosto | J7: Septiembre | K7: Octubre | L7: Noviembre | M7: Diciembre
A8: RESIDENCIAL
A9: T-RE
A10: Primeros 200 KWh | B10: 69 | C10: 69 | D10: 69 | E10: 73 | F10: 73 | G10: 73 | H10: 74 | I10: 74 | J10: 74 | K10: 69 | L10: 69 | M10: 69
A11: kWh adicional | B11: 97 | C11: 97 | D11: 97 | E11: 104 | F11: 104 | G11: 104 | H11: 104 | I11: 104 | J11: 104 | K11: 98 | L11: 98 | M11: 98
A12: GENERAL
A13: T-GE
A14: Energía_Bloq. ≤3.000 KWh | B14: 101 | C14: 101 | D14: 101 | E14: 108 | F14: 108 | G14: 108 | H14: 109 | I14: 109 | J14: 109 | K14: 102 | L14: 102 | M14: 102
A15: Energía_Bloq. >3.000 KWh (primeros 3000 KWh) | B15: 192000 | C15: 192000 | D15: 192000 | E15: 207000 | F15: 207000 | G15: 207000 | H15: 207000 | I15: 207000 | J15: 207000 | K15: 195000 | L15: 195000 | M15: 195000
A16: Energía_Bloq. >3.000 KWh (KWh adicional) | B16: 64 | C16: 64 | D16: 64 | E16: 69 | F16: 69 | G16: 69 | H16: 69 | I16: 69 | J16: 69 | K16: 65 | L16: 65 | M16: 65
A17: Potencia_Menor igual al diferencial (mínimo) | B17: 94800 | C17: 94800 | D17: 94800 | E17: 101350 | F17: 101350 | G17: 101350 | H17: 102050 | I17: 102050 | J17: 102050 | K17: 95580 | L17: 95580 | M17: 95580
A18: Potencia_Mayor al diferencial (adicional) | B18: 9480 | C18: 9480 | D18: 9480 | E18: 10135 | F18: 10135 | G18: 10135 | H18: 10205 | I18: 10205 | J18: 10205 | K18: 9558 | L18: 9558 | M18: 9558
A19: MEDIA TENSIÓN (T-MT)
A20: T-MT
A21: Energía_Punta | B21: 84 | C21: 84 | D21: 84 | E21: 90 | F21: 90 | G21: 90 | H21: 91 | I21: 91 | J21: 91 | K21: 85 | L21: 85 | M21: 85
A22: Energía_Valle | B22: 73 | C22: 73 | D22: 73 | E22: 78 | F22: 78 | G22: 78 | H22: 79 | I22: 79 | J22: 79 | K22: 74 | L22: 74 | M22: 74
A23: Energía_Noche | B23: 65 | C23: 65 | D23: 65 | E23: 70 | F23: 70 | G23: 70 | H23: 70 | I23: 70 | J23: 70 | K23: 66 | L23: 66 | M23: 66
A24: Potencia_Punta | B24: 3826 | C24: 3826 | D24: 3826 | E24: 4091 | F24: 4091 | G24: 4091 | H24: 4119 | I24: 4119 | J24: 4119 | K24: 3858 | L24: 3858 | M24: 3858
A25: Potencia_Valle | B25: 3826 | C25: 3826 | D25: 3826 | E25: 4091 | F25: 4091 | G25: 4091 | H25: 4119 | I25: 4119 | J25: 4119 | K25: 3858 | L25: 3858 | M25: 3858
A26: ALUMBRADO PÚBLICO
A27: T-AP
A28: Cada KWh | B28: 2.19 | C28: 2.19 | D28: 2.19 | E28: 2.19 | F28: 2.19 | G28: 2.19 | H28: 2.19 | I28: 2.19 | J28: 2.19 | K28: 2.19 | L28: 2.19 | M28: 2.19

Sheet CS 2014
A5: Tabla 8
A6: Tarifas del servicio de distribución eléctrica y alumbrado público prestado por CoopeSantos R.L para el año 2014, según el mes y el tipo de tarifa respectivo.
A7: Tipo de tarifa y bloque | B7: Enero | C7: Febrero | D7: Marzo | E7: Abril | F7: Mayo | G7: Junio | H7: Julio | I7: Agosto | J7: Septiembre | K7: Octubre | L7: Noviembre | M7: Diciembre
A8: RESIDENCIAL
A9: T-RE
A10: Primeros 200 KWh | B10: 79 | C10: 79 | D10: 79 | E10: 86 | F10: 86 | G10: 86 | H10: 87 | I10: 87 | J10: 87 | K10: 82 | L10: 82 | M10: 82
A11: kWh adicional | B11: 127 | C11: 127 | D11: 127 | E11: 140 | F11: 140 | G11: 140 | H11: 142 | I11: 142 | J11: 142 | K11: 133 | L11: 133 | M11: 133
A12: GENERAL
A13: T-GE
A14: Energía_Bloq. ≤3.000 KWh | B14: 151 | C14: 151 | D14: 151 | E14: 167 | F14: 167 | G14: 167 | H14: 169 | I14: 169 | J14: 169 | K14: 159 | L14: 159 | M14: 159
A15: Energía_Bloq. >3.000 KWh (primeros 3000 KWh) | B15: 273000 | C15: 273000 | D15: 273000 | E15: 303000 | F15: 303000 | G15: 303000 | H15: 306000 | I15: 306000 | J15: 306000 | K15: 288000 | L15: 288000 | M15: 288000
A16: Energía_Bloq. >3.000 KWh (KWh adicional) | B16: 91 | C16: 91 | D16: 91 | E16: 101 | F16: 101 | G16: 101 | H16: 102 | I16: 102 | J16: 102 | K16: 96 | L16: 96 | M16: 96
A17: Potencia_Menor igual al diferencial (mínimo) | B17: 224160 | C17: 224160 | D17: 224160 | E17: 248190 | F17: 248190 | G17: 248190 | H17: 251550 | I17: 251550 | J17: 251550 | K17: 236505 | L17: 236505 | M17: 236505
A18: Potencia_Mayor al diferencial (adicional) | B18: 14944 | C18: 14944 | D18: 14944 | E18: 16546 | F18: 16546 | G18: 16546 | H18: 16770 | I18: 16770 | J18: 16770 | K18: 15767 | L18: 15767 | M18: 15767
A19: PREFERENCIAL
A20: T-CS
A21: Energía_Bloq. ≤ 250 KWh | B21: 109 | C21: 109 | D21: 109 | E21: 119 | F21: 119 | G21: 119 | H21: 121 | I21: 121 | J21: 121 | K21: 114 | L21: 114 | M21: 114
A22: Energía_Bloq. De 251 a 3.000 KWh | B22: 151 | C22: 151 | D22: 151 | E22: 167 | F22: 167 | G22: 167 | H22: 169 | I22: 169 | J22: 169 | K22: 159 | L22: 159 | M22: 159
A23: Energía_Bloq. >3.000 KWh (primeros 3000 KWh) | B23: 273000 | C23: 273000 | D23: 273000 | E23: 303000 | F23: 303000 | G23: 303000 | H23: 306000 | I23: 306000 | J23: 306000 | K23: 288000 | L23: 288000 | M23: 288000
A24: Energía_Bloq. >3.000 KWh (KWh adicional) | B24: 91 | C24: 91 | D24: 91 | E24: 101 | F24: 101 | G24: 101 | H24: 102 | I24: 102 | J24: 102 | K24: 96 | L24: 96 | M24: 96
A25: Potencia_Menor igual al diferencial (mínimo) | B25: 224160 | C25: 224160 | D25: 224160 | E25: 248190 | F25: 248190 | G25: 248190 | H25: 251550 | I25: 251550 | J25: 251550 | K25: 236505 | L25: 236505 | M25: 236505
A26: Potencia_Mayor al diferencial (adicional) | B26: 14944 | C26: 14944 | D26: 14944 | E26: 16546 | F26: 16546 | G26: 16546 | H26: 16770 | I26: 16770 | J26: 16770 | K26: 15767 | L26: 15767 | M26: 15767
A27: MEDIA TENSIÓN (T-MT)
A28: T-MT
A29: Energía_Punta | B29: 68 | C29: 68 | D29: 68 | E29: 79 | F29: 79 | G29: 79 | H29: 81 | I29: 81 | J29: 81 | K29: 76 | L29: 76 | M29: 76
A30: Energía_Valle | B30: 29 | C30: 29 | D30: 29 | E30: 32 | F30: 32 | G30: 32 | H30: 32 | I30: 32 | J30: 32 | K30: 30 | L30: 30 | M30: 30
A31: Energía_Noche | B31: 19 | C31: 19 | D31: 19 | E31: 20 | F31: 20 | G31: 20 | H31: 21 | I31: 21 | J31: 21 | K31: 19 | L31: 19 | M31: 19
A32: Potencia_Punta | B32: 11055 | C32: 11055 | D32: 11055 | E32: 12140 | F32: 12140 | G32: 12140 | H32: 12305 | I32: 12305 | J32: 12305 | K32: 11569 | L32: 11569 | M32: 11569
A33: Potencia_Valle | B33: 7927 | C33: 7927 | D33: 7927 | E33: 8819 | F33: 8819 | G33: 8819 | H33: 8938 | I33: 8938 | J33: 8938 | K33: 8404 | L33: 8404 | M33: 8404
A34: Potencia_Noche | B34: 5056 | C34: 5056 | D34: 5056 | E34: 5552 | F34: 5552 | G34: 5552 | H34: 5627 | I34: 5627 | J34: 5627 | K34: 5291 | L34: 5291 | M34: 5291
A35: ALUMBRADO PÚBLICO
A36: T-AP
A37: Cada KWh | B37: 3.72 | C37: 3.72 | D37: 3.72 | E37: 3.72 | F37: 3.72 | G37: 3.72 | H37: 3.72 | I37: 3.72 | J37: 3.72 | K37: 3.72 | L37: 3.72 | M37: 3.72

Sheet CAR 2014
A4: Tabla 9
A5: Tarifas del servicio de distribución eléctrica y alumbrado público prestado por CoopeAlfaroRuiz R.L para el año 2014, según el mes y el tipo de tarifa respectivo.
A6: Tipo de tarifa y bloque | B6: Enero | C6: Febrero | D6: Marzo | E6: Abril | F6: Mayo | G6: Junio | H6: Julio | I6: Agosto | J6: Septiembre | K6: Octubre | L6: Noviembre | M6: Diciembre
A7: RESIDENCIAL
A8: T-RE
A9: Primeros 200 KWh | B9: 68 | C9: 68 | D9: 68 | E9: 73 | F9: 73 | G9: 73 | H9: 74 | I9: 74 | J9: 74 | K9: 69 | L9: 69 | M9: 69
A10: kWh adicional | B10: 88 | C10: 88 | D10: 88 | E10: 94 | F10: 94 | G10: 94 | H10: 96 | I10: 96 | J10: 96 | K10: 90 | L10: 90 | M10: 90
A11: GENERAL
A12: T-GE
A13: Energía_Bloq. ≤3.000 KWh | B13: 95 | C13: 95 | D13: 95 | E13: 102 | F13: 102 | G13: 102 | H13: 104 | I13: 104 | J13: 104 | K13: 97 | L13: 97 | M13: 97
A14: Energía_Bloq. >3.000 KWh (primeros 3000 KWh) | B14: 174000 | C14: 174000 | D14: 174000 | E14: 186000 | F14: 186000 | G14: 186000 | H14: 189000 | I14: 189000 | J14: 189000 | K14: 177000 | L14: 177000 | M14: 177000
A15: Energía_Bloq. >3.000 KWh (KWh adicional) | B15: 58 | C15: 58 | D15: 58 | E15: 62 | F15: 62 | G15: 62 | H15: 63 | I15: 63 | J15: 63 | K15: 59 | L15: 59 | M15: 59
A16: Potencia_Menor igual al diferencial (mínimo) | B16: 135375 | C16: 135375 | D16: 135375 | E16: 144795 | F16: 144795 | G16: 144795 | H16: 147375 | I16: 147375 | J16: 147375 | K16: 138150 | L16: 138150 | M16: 138150
A17: Potencia_Mayor al diferencial (adicional) | B17: 9025 | C17: 9025 | D17: 9025 | E17: 9653 | F17: 9653 | G17: 9653 | H17: 9825 | I17: 9825 | J17: 9825 | K17: 9210 | L17: 9210 | M17: 9210
A18: ALUMBRADO PÚBLICO
A19: T-AP
A20: Cada KWh | B20: 3.18 | C20: 3.18 | D20: 3.18 | E20: 3.18 | F20: 3.18 | G20: 3.18 | H20: 3.18 | I20: 3.18 | J20: 3.18 | K20: 3.18 | L20: 3.18 | M20: 3.18

Sheet 2015
B2: Seleccione la empresa que desea consultar:

Sheet ICE 2015
A5: Tabla 1
A6: Tarifas del servicio de generación eléctrica prestado por el ICE para el año 2015, según el mes y el tipo de tarifa respectivo.
A7: =[1]ICE!B50 -> Tipo de tarifa y bloque | B7: =[1]ICE!C50 -> Enero | C7: =[1]ICE!D50 -> Febrero | D7: =[1]ICE!E50 -> Marzo | E7: =[1]ICE!F50 -> Abril | F7: =[1]ICE!G50 -> Mayo | G7: =[1]ICE!H50 -> Junio | H7: =[1]ICE!I50 -> Julio | ... M7: =[1]ICE!N50 -> Diciembre
A8: =[1]ICE!B51 -> VENTAS A ICE DISTRIBUCIÓN Y A LA CNFL
A9: =[1]ICE!B52 -> T-CB
A10: =[1]ICE!B53 -> Energía Punta | B10: =[1]ICE!C53 -> 53 | C10: =[1]ICE!D53 -> 53 | D10: =[1]ICE!E53 -> 60.7 | E10: =[1]ICE!F53 -> 50.8 | F10: =[1]ICE!G53 -> 50.8 | G10: =[1]ICE!H53 -> 50.8 | H10: =[1]ICE!I53 -> 47.87 | ... M10: =[1]ICE!N53 -> 49.24
A11: =[1]ICE!B54 -> Energía Valle | B11: =[1]ICE!C54 -> 44 | C11: =[1]ICE!D54 -> 44 | D11: =[1]ICE!E54 -> 49.7 | E11: =[1]ICE!F54 -> 41.6 | F11: =[1]ICE!G54 -> 41.6 | G11: =[1]ICE!H54 -> 41.6 | H11: =[1]ICE!I54 -> 39.15 | ... M11: =[1]ICE!N54 -> 40.28
A12: =[1]ICE!B55 -> Energía Noche | B12: =[1]ICE!C55 -> 37 | C12: =[1]ICE!D55 -> 37 | D12: =[1]ICE!E55 -> 42.2 | E12: =[1]ICE!F55 -> 35.4 | F12: =[1]ICE!G55 -> 35.4 | G12: =[1]ICE!H55 -> 35.4 | H12: =[1]ICE!I55 -> 33.31 | ... M12: =[1]ICE!N55 -> 34.27
A13: =[1]ICE!B56 -> Potencia Punta | B13: =[1]ICE!C56 -> 2825 | C13: =[1]ICE!D56 -> 2825 | D13: =[1]ICE!E56 -> 3219 | E13: =[1]ICE!F56 -> 2696 | F13: =[1]ICE!G56 -> 2696 | G13: =[1]ICE!H56 -> 2696 | H13: =[1]ICE!I56 -> 2538.83 | ... M13: =[1]ICE!N56 -> 2611.87
A14: =[1]ICE!B57 -> Potencia Valle | B14: =[1]ICE!C57 -> 2825 | C14: =[1]ICE!D57 -> 2825 | D14: =[1]ICE!E57 -> 3219 | E14: =[1]ICE!F57 -> 2696 | F14: =[1]ICE!G57 -> 2696 | G14: =[1]ICE!H57 -> 2696 | H14: =[1]ICE!I57 -> 2538.83 | ... M14: =[1]ICE!N57 -> 2611.87
A15: =[1]ICE!B58 -> Potencia Noche
A16: =[1]ICE!B59 -> VENTAS AL SERVICIO DE DISTRIBUCIÓN
A17: =[1]ICE!B60 -> T-SD
